Workbook

Sheet Scrum Daily
A1: Scrum Daily · Sprint 1 · TicketFlow (SDGE)
A2: 9 – 28 de septiembre de 2026 · Reunión diaria de 15 minutos. Columnas blancas: salen de Jira. Columnas amarillas: las llena cada integrante con lo que dijo en la reunión.
A4: Fecha | B4: Integrante | C4: Historia en curso (Jira) | D4: ¿Qué hice ayer? | E4: ¿Qué haré hoy? | F4: Impedimento | G4: Solución | H4: Avance del sprint
A5: 46274 | B5: Eder | C5: SDGE-2 · Maquetación de la página de inicio SDGE-3 · Encabezado con navegación y botones de sesión | H5: =Burndown!H5
A6: 46274 | B6: Eduardo | C6: SDGE-1 · Interfaz de inicio de sesión | H6: =Burndown!H5
A7: 46274 | B7: Jorge | C7: SDGE-12 · Hoja de estilos del sistema de diseño | H7: =Burndown!H5
A8: 46274 | B8: Samuel | C8: SDGE-6 · Interfaz de registro de administrador | H8: =Burndown!H5
A9: 46275 | B9: Eder | C9: SDGE-2 · Maquetación de la página de inicio SDGE-3 · Encabezado con navegación y botones de sesión | H9: =Burndown!H6
A10: 46275 | B10: Eduardo | C10: SDGE-1 · Interfaz de inicio de sesión | H10: =Burndown!H6
A11: 46275 | B11: Jorge | C11: SDGE-12 · Hoja de estilos del sistema de diseño | H11: =Burndown!H6
A12: 46275 | B12: Samuel | C12: SDGE-6 · Interfaz de registro de administrador | H12: =Burndown!H6
A13: 46276 | B13: Eder | C13: SDGE-2 · Maquetación de la página de inicio SDGE-4 · Sección hero con buscador de eventos | H13: =Burndown!H7
A14: 46276 | B14: Eduardo | C14: SDGE-7 · Interfaz de registro de cliente | H14: =Burndown!H7
A15: 46276 | B15: Jorge | C15: SDGE-12 · Hoja de estilos del sistema de diseño | H15: =Burndown!H7
A16: 46276 | B16: Samuel | C16: SDGE-8 · Validación de formularios en el navegador SDGE-11 · Sección de eventos destacados y categorías | H16: =Burndown!H7
A17: 46279 | B17: Eder | C17: SDGE-2 · Maquetación de la página de inicio SDGE-4 · Sección hero con buscador de eventos | H17: =Burndown!H8
A18: 46279 | B18: Eduardo | C18: SDGE-7 · Interfaz de registro de cliente | H18: =Burndown!H8
A19: 46279 | B19: Jorge | C19: Sin historia asignada | H19: =Burndown!H8
A20: 46279 | B20: Samuel | C20: SDGE-8 · Validación de formularios en el navegador SDGE-11 · Sección de eventos destacados y categorías | H20: =Burndown!H8
A21: 46280 | B21: Eder | C21: SDGE-2 · Maquetación de la página de inicio SDGE-4 · Sección hero con buscador de eventos | H21: =Burndown!H9
A22: 46280 | B22: Eduardo | C22: SDGE-7 · Interfaz de registro de cliente | H22: =Burndown!H9
A23: 46280 | B23: Jorge | C23: Sin historia asignada | H23: =Burndown!H9
A24: 46280 | B24: Samuel | C24: SDGE-8 · Validación de formularios en el navegador SDGE-11 · Sección de eventos destacados y categorías | H24: =Burndown!H9
A25: 46281 | B25: Eder | C25: SDGE-2 · Maquetación de la página de inicio SDGE-4 · Sección hero con buscador de eventos | H25: =Burndown!H10
A26: 46281 | B26: Eduardo | C26: SDGE-7 · Interfaz de registro de cliente | H26: =Burndown!H10
A27: 46281 | B27: Jorge | C27: Sin historia asignada | H27: =Burndown!H10
A28: 46281 | B28: Samuel | C28: SDGE-8 · Validación de formularios en el navegador SDGE-11 · Sección de eventos destacados y categorías | H28: =Burndown!H10
A29: 46282 | B29: Eder | C29: SDGE-4 · Sección hero con buscador de eventos | H29: =Burndown!H11
A30: 46282 | B30: Eduardo | C30: SDGE-9 · Interfaz de registro de agente | H30: =Burndown!H11
A31: 46282 | B31: Jorge | C31: SDGE-10 · Ajuste responsive de las interfaces de registro | H31: =Burndown!H11
A32: 46282 | B32: Samuel | C32: SDGE-8 · Validación de formularios en el navegador | H32: =Burndown!H11
A33: 46283 | B33: Eder | C33: SDGE-4 · Sección hero con buscador de eventos | H33: =Burndown!H12
A34: 46283 | B34: Eduardo | C34: SDGE-9 · Interfaz de registro de agente | H34: =Burndown!H12
A35: 46283 | B35: Jorge | C35: SDGE-10 · Ajuste responsive de las interfaces de registro | H35: =Burndown!H12
A36: 46283 | B36: Samuel | C36: SDGE-8 · Validación de formularios en el navegador | H36: =Burndown!H12
A37: 46286 | B37: Eder | C37: SDGE-4 · Sección hero con buscador de eventos | H37: =Burndown!H13
A38: 46286 | B38: Eduardo | C38: SDGE-9 · Interfaz de registro de agente | H38: =Burndown!H13
A39: 46286 | B39: Jorge | C39: SDGE-10 · Ajuste responsive de las interfaces de registro | H39: =Burndown!H13
A40: 46286 | B40: Samuel | C40: SDGE-8 · Validación de formularios en el navegador | H40: =Burndown!H13
A41: 46287 | B41: Eder | C41: SDGE-21 · Consolidar la estructura del repositorio en GitHub | H41: =Burndown!H14
...

Sheet Burndown
A1: Indicador de avance · Burndown del Sprint 1
A2: Puntos pendientes al cierre de cada día hábil. Los puntos terminados salen de la fecha en que cada historia pasó a Finalizada en Jira. El 22/09 el alcance subió de 49 a 56 SP (SDGE-14, SDGE-21 y SDGE-26).
A4: Día | B4: Fecha | C4: Alcance (SP) | D4: Terminados ese día (SP) | E4: Terminados acumulados (SP) | F4: Pendientes reales (SP) | G4: Pendientes ideales (SP) | H4: Avance del sprint
A5: 1 | B5: 46274 | C5: 49 | D5: 0 | E5: =SUM($D$5:D5) | F5: =C5-E5 | G5: =ROUND($C$5*(1-(A5-1)/13),1) | H5: =E5/C5
A6: 2 | B6: 46275 | C6: 49 | D6: 0 | E6: =SUM($D$5:D6) | F6: =C6-E6 | G6: =ROUND($C$5*(1-(A6-1)/13),1) | H6: =E6/C6
A7: 3 | B7: 46276 | C7: 49 | D7: 0 | E7: =SUM($D$5:D7) | F7: =C7-E7 | G7: =ROUND($C$5*(1-(A7-1)/13),1) | H7: =E7/C7
A8: 4 | B8: 46279 | C8: 49 | D8: 14 | E8: =SUM($D$5:D8) | F8: =C8-E8 | G8: =ROUND($C$5*(1-(A8-1)/13),1) | H8: =E8/C8
A9: 5 | B9: 46280 | C9: 49 | D9: 0 | E9: =SUM($D$5:D9) | F9: =C9-E9 | G9: =ROUND($C$5*(1-(A9-1)/13),1) | H9: =E9/C9
A10: 6 | B10: 46281 | C10: 49 | D10: 0 | E10: =SUM($D$5:D10) | F10: =C10-E10 | G10: =ROUND($C$5*(1-(A10-1)/13),1) | H10: =E10/C10
A11: 7 | B11: 46282 | C11: 49 | D11: 0 | E11: =SUM($D$5:D11) | F11: =C11-E11 | G11: =ROUND($C$5*(1-(A11-1)/13),1) | H11: =E11/C11
A12: 8 | B12: 46283 | C12: 49 | D12: 15 | E12: =SUM($D$5:D12) | F12: =C12-E12 | G12: =ROUND($C$5*(1-(A12-1)/13),1) | H12: =E12/C12
A13: 9 | B13: 46286 | C13: 49 | D13: 0 | E13: =SUM($D$5:D13) | F13: =C13-E13 | G13: =ROUND($C$5*(1-(A13-1)/13),1) | H13: =E13/C13
A14: 10 | B14: 46287 | C14: 56 | D14: 18 | E14: =SUM($D$5:D14) | F14: =C14-E14 | G14: =ROUND($C$5*(1-(A14-1)/13),1) | H14: =E14/C14
A15: 11 | B15: 46288 | C15: 56 | G15: =ROUND($C$5*(1-(A15-1)/13),1)
A16: 12 | B16: 46289 | C16: 56 | G16: =ROUND($C$5*(1-(A16-1)/13),1)
A17: 13 | B17: 46290 | C17: 56 | G17: =ROUND($C$5*(1-(A17-1)/13),1)
A18: 14 | B18: 46293 | C18: 56 | G18: =ROUND($C$5*(1-(A18-1)/13),1)
A20: Celdas amarillas: días que aún no han pasado. Se llenan con los puntos que se terminen ese día.

Sheet Impedimentos
A1: Impedimentos del Sprint 1 y su solución
A2: Solo los que dejaron rastro verificable en Git, Jira o el README. Agreguen debajo los que salieron en las reuniones.
A4: Fecha | B4: Integrante | C4: Impedimento | D4: Solución | E4: Estado | F4: Evidencia
A5: Sprint 1 | B5: Samuel | C5: Samuel no aparecía en el proyecto de Jira, así que sus historias no tenían responsable. | D5: Se le invitó al proyecto y se repartió el sprint entre los cuatro integrantes. | E5: Resuelto | F5: Jira: SDGE-6, SDGE-8 y SDGE-11 asignadas a Samuel
A6: Sprint 1 | B6: Samuel | C6: La pantalla de registro de administrador no existía en el diseño de Figma. | D6: Se diseñó sobre el mismo sistema de diseño, con código de invitación y correo institucional. | E6: Resuelto | F6: Jira SDGE-6 · README, nota sobre el registro de administrador
A7: 12/09/2026 | B7: Eder | C7: GitHub rechazó el primer push por falta de permisos en la cuenta. | D7: Se corrigió el acceso de la cuenta al repositorio y se subió el Sprint 1. | E7: Resuelto | F7: Git: commit c2332cc
A8: 12/09/2026 | B8: Todos | C8: Retroalimentación del profesor: los colores se confundían y sobraba espacio en blanco. | D8: Se unificó el color de las categorías y se redujo la separación entre secciones de 80 a 56 px. | E8: Resuelto | F8: Git: commits 65a306a y cbb30c9
A9: 22/09/2026 | B9: Jorge | C9: La hoja de estilos estaba escrita para escritorio (max-width) y no cumplía con Mobile-First. | D9: Se creó SDGE-14 y se reescribió con estilos base de celular y min-width. | E9: Resuelto | F9: Jira SDGE-14 · Git: commit 111cd85
A10: 22/09/2026 | B10: Jorge | C10: En el menú de celular, los enlaces y los botones se abrían uno encima del otro. | D10: El menú ahora se despliega en el flujo, debajo del logo. | E10: Resuelto | F10: Git: commit 111cd85
A11: 22/09/2026 | B11: Samuel | C11: SDGE-11 tenía la fecha de inicio (17/09) después de la de vencimiento (16/09). | D11: Se corrigió a 11/09 – 16/09, como estaba en la planeación. | E11: Resuelto | F11: Jira SDGE-11
A12: 22/09/2026 | B12: Eder | C12: Los compañeros todavía no son colaboradores del repositorio en GitHub. | D12: Invitarlos desde Settings → Collaborators. | E12: Pendiente | F12: Jira SDGE-24

Sheet Resumen
A1: Resumen del Sprint 1
A2: Se actualiza solo a partir del Burndown.
A4: Indicador | B4: Valor
A5: Puntos comprometidos (alcance final) | B5: =Burndown!C18
A6: Puntos terminados a hoy (22/09) | B6: =Burndown!E14
A7: Puntos pendientes a hoy | B7: =Burndown!F14
A8: Avance del sprint a hoy | B8: =Burndown!H14
A9: Historias y tareas en el sprint | B9: 14
A10: Historias y tareas terminadas | B10: 11
A11: Impedimentos resueltos | B11: =COUNTIF(Impedimentos!E:E,"Resuelto")
A12: Impedimentos pendientes | B12: =COUNTIF(Impedimentos!E:E,"Pendiente")+COUNTIF(Impedimentos!E:E,"En curso")
A15: Carga por integrante (SP)
A16: Integrante | B16: SP asignados
A17: Eder Fabián Rodríguez Murillo | B17: 14
A18: Eduardo José Benítez Guevara | B18: 16
A19: Jorge Andrés Marín Díaz | B19: 13
A20: Samuel Uribe Naranjo | B20: 13
